Workbook
Name AF_WP_2abe5ace68e3430caf1789240185e72e_104732: '1. PPE'!#REF!
Name AF_WP_bbae28558148406dab21e64046d19ef0_74606: '[1]2. FY2024 Fixed Assets'!$E$250
Name AF_WP_c03e73d17fed40d2b36611c1cef99d2b_104746: '1. PPE'!$I$19

Sheet 1. PPE
G1: Tab-2 FY 2024 Additions
D2: W/P | J2: (Additions)
B3: GL Account | C3: Description | D3: Ref PY | F3: FY2023 Balance | G3: FY2024 Additions | H3: FY2024 Ending Balance | I3: W/P REF | J3: FY2024 Net Changes
B4: 15010 | C4: Land | E4: F-4 | F4: ='3. FY 2024 PPE'!D11 -> 69139.15 | G4: 0 | H4: =F4+G4 -> 69139.15 | I4: F-Lead / R-1.1
B5: 15020 | C5: Fixed Assets:Buildings | F5: 1075469.8 | G5: 0 | H5: =F5+G5 -> 1075469.8
B6: 15030 | C6: Fixed Assets:Leasehold Improvements | F6: 0 | G6: ='2. FY 2024 Addition Listing '!E50 -> 425243.63 | H6: =F6+G6 -> 425243.63
B7: 15040 | C7: Fixed Assets:Furniture and Equipment | F7: 386253.09 | G7: ='2. FY 2024 Addition Listing '!E59 -> 25548.26 | H7: =F7+G7 -> 411801.35
B8: PP&E | F8: =SUM(F4:F7) -> 1530862.1 | G8: =SUM(G4:G7) -> 450791.89 | H8: =SUM(H4:H7) -> 1981654 | J8: =G8 -> 450791.89 | K8: Tab 2 - Row-E49
B10: 15021 | C10: Accumulated Depreciation Building | F10: -535176.85 | G10: =-'3. FY 2024 PPE'!H21 -> -73703.717 | H10: =SUM(F10:G10) -> -608880.57
B11: 15041 | C11: Accumulated Depreciation Furniture & Fixtures | F11: -335779.32 | G11: =-'3. FY 2024 PPE'!H28 -> -24889.33 | H11: =SUM(F11:G11) -> -360668.65
C12: Less: Accumulated Depreciation | F12: =SUM(F10:F11) -> -870956.17 | G12: =SUM(G10:G11) -> -98593.047 | H12: =SUM(H10:H11) -> -969549.22 | J12: =G12 -> -98593.047 | K12: Tab 3 - Row-H30
G13: =-F19 -> -66593.72 | J13: =G13 -> -66593.72 | K13: PY
C15: PP&E, Net | F15: =F8+F12 -> 659905.9 | G15: =G8+G12 -> 352198.84 | H15: =H8+H12 -> 1012104.7
F18: FY2023 | G18: WPG Analysis | H18: FY2024
D19: Depreciation | E19: TB | F19: =66593.72 -> 66593.72 | H19: =-G12 -> 98593.047 | I19: 50-LS
D20: Depreciable PP&E | F20: =F8 -> 1530862.1 | H20: =H8 -> 1981654
D21: Ratio | F21: =F19/F20 -> 0.043500797 | H21: =H19/H20 -> 0.049752908
D22: Note: | F22: No significant increase or decrease in assets. Depreciation remained constant
F23: in both years despite 2024 additions.
A24: TICKMARKS:
B25: Crossfooted
B26: Recalculation
B27: Footed

Sheet 2. FY 2024 Addition Listing 
A1: TURNER THEOLOGICAL SEMINARY
A2: Fixed Asset Addition Testing
A3: 45473
B6: Purpose: | C6: To test the addition in PPE during the FY 2024.
B8: Scope: | C8: Reviewed the significant fixed asset additions to cover atleast 75% of total additions.
B10: Source: | C10: Fixed Asset additions listing.
B11: Conclusion: | C11: WPG noted 19 samples (highlighted in orange) based on above criteria. Refer "F-1.1" for testing document.
A13: GL Name | B13: Date | C13: Vendor | D13: Memo/Description | E13: Amount
A14: Leasehold Improvements
B15: 06/01/2024 | C15: VKY Renovation LLC | D15: Bathroom renovations - Deposit | E15: 65994
B16: 06/06/2024 | C16: VKY Renovation LLC | D16: Check 30357 | E16: 65994
B17: 02/20/2024 | C17: A & D Gray Enterprises Inc | D17: Maintenance | E17: 29128.69
B18: 06/05/2024 | C18: D & L Contracting Services, Inc | D18: Renovations | E18: 25000
B19: 08/29/2023 | C19: A & D Gray Enterprises Inc | D19: GUSTO/CND 435819 Turner Theological Sem | E19: 16550
B20: 10/19/2023 | C20: A & D Gray Enterprises Inc | D20: GUSTO/CND 698958 Turner Theological Sem | E20: 15044.5
B21: 11/30/2023 | C21: A & D Gray Enterprises Inc | D21: GUSTO/CND 660665 Turner Theological Sem | E21: 15044.5
B22: 07/07/2023 | C22: A & D Gray Enterprises Inc | E22: 15000
B23: 08/14/2023 | C23: A & D Gray Enterprises Inc | D23: GUSTO/CND 106053 Turner Theological Sem | E23: 15000
B24: 07/21/2023 | C24: A & D Gray Enterprises Inc | E24: 14110
B25: 07/26/2023 | C25: A & D Gray Enterprises Inc | E25: 12565
B26: 08/17/2023 | C26: D & L Contracting Services, Inc | D26: GUSTO/CND 212070 Turner Theological Sem | E26: 10000
B27: 09/19/2023 | C27: D & L Contracting Services, Inc | D27: GUSTO/CND 976026 Turner Theological Sem | E27: 10000
B28: 10/19/2023 | C28: D & L Contracting Services, Inc | D28: GUSTO/CND 698958 Turner Theological Sem | E28: 10000
B29: 06/12/2024 | C29: A & D Gray Enterprises Inc | D29: Deposit on Renovation of 3rd and 4th of Talbot Hall | E29: 9000
B30: 08/17/2023 | C30: Residential Specialist LLC | D30: GUSTO/CND 212070 Turner Theological Sem | E30: 8218.62
B31: 11/30/2023 | C31: Residential Specialist LLC | D31: GUSTO/CND 660665 Turner Theological Sem | E31: 8218.62
B32: 11/30/2023 | C32: Schindler Elevator Corp | D32: Theological; Schindler Elevat/XXXXXX5526 Turner | E32: 6332.05
B33: 11/14/2023 | C33: A & D Gray Enterprises Inc | D33: GUSTO/CND 271426 Turner Theological Sem | E33: 5065.52
B34: 07/17/2023 | C34: D & L Contracting Services, Inc | E34: 5000
B35: 07/19/2023 | C35: Schindler Elevator Corp | D35: SCHINDLER ELEVAT/8662465526 TURNER THEOLOGICAL | E35: 5000
B36: 09/14/2023 | C36: Schindler Elevator Corp | D36: Theological; Schindler Elevat/8662465526 Turner | E36: 5000
B37: 10/16/2023 | C37: Schindler Elevator Corp | D37: Theological; Schindler Elevat/8662465526 Turner | E37: 5000
B38: 11/16/2023 | C38: D & L Contracting Services, Inc | D38: GUSTO/CND 364686 Turner Theological Sem | E38: 5000
B39: 11/20/2023 | C39: Schindler Elevator Corp | D39: Theological; Schindler Elevat/8662465526 Turner | E39: 5000
B40: 11/30/2023 | C40: A & D Gray Enterprises Inc | D40: GUSTO/CND 660665 Turner Theological Sem | E40: 5000
B41: 01/23/2024 | C41: D & L Contracting Services, Inc | D41: Maintenance | E41: 5000
B42: 02/16/2024 | C42: D & L Contracting Services, Inc | D42: Maintenance | E42: 5000
B43: 04/10/2024 | C43: D & L Contracting Services, Inc | D43: Maintenance | E43: 5000
B44: 05/08/2024 | C44: D & L Contracting Services, Inc | D44: Renovations | E44: 5000
B45: 09/19/2023 | C45: A & D Gray Enterprises Inc | D45: GUSTO/CND 976026 Turner Theological Sem | E45: 4630.54
...

Sheet 3. FY 2024 PPE
A1: Turner Theological Seminary
A2: Fixed Asset Additions
A4: BOOK ASSET DETAIL
A5: 7/1/2023 - 6/30/2024
A7: FY 2024 | J7: 45473
A8: Description | C8: Year | D8: Cost | E8: Useful Life | F8: Method | G8: Beg. Accum. Deprec. | H8: Depreciation | I8: End. Accum. Deprec. | J8: Net Book Value | L8: Depreciation Recalculation (WPG) | N8: WPG Notes
A9: Land
A11: Land-Building | C11: 1986 | D11: 69139.15 | G11: 0 | H11: 0 | I11: =+G11+H11 -> 0 | J11: =+D11-I11 -> 69139.15 | L11: 0
A13: Buildings
A15: Buildings and Improvements | C15: 1986 | D15: =701391.48-D11 -> 632252.33 | E15: 40 | F15: S/L | G15: 500966.2 | H15: =+D15/E15 -> 15806.308 | I15: =+G15+H15 -> 516772.5 | J15: =+D15-I15 -> 115479.83 | L15: =D15/E15 -> 15806.308 | N15: Note 1
B16: Improvements | C16: 2022 | D16: 33117.29 | E16: 15 | F16: S/L | G16: 4415.6387 | H16: =+D16/E16 -> 2207.8193 | I16: =+G16+H16 -> 6623.458 | J16: =+D16-I16 -> 26493.832 | L16: =D16/E16 -> 2207.8193
B17: Improvements | C17: 2022 | D17: 36825 | E17: 15 | F17: S/L | G17: 4910 | H17: =+D17/E17 -> 2455 | I17: =+G17+H17 -> 7365 | J17: =+D17-I17 -> 29460 | L17: =D17/E17 -> 2455
B18: Improvements | C18: 2023 | D18: =300775.21 -> 300775.21 | E18: 15 | F18: S/L | G18: 20051.681 | H18: =+D18/E18 -> 20051.681 | I18: =+G18+H18 -> 40103.361 | J18: =+D18-I18 -> 260671.85 | L18: =D18/E18 -> 20051.681
B19: Improvements | C19: 2023 | D19: 72500 | E19: 15 | F19: S/L | G19: 4833.3333 | H19: =+D19/E19 -> 4833.3333 | I19: =+G19+H19 -> 9666.6667 | J19: =+D19-I19 -> 62833.333 | L19: =D19/E19 -> 4833.3333
B20: Improvements | C20: 2024 | D20: 425243.63 | E20: 15 | F20: S/L | G20: 0 | H20: =+D20/E20 -> 28349.575 | I20: =+G20+H20 -> 28349.575 | J20: =+D20-I20 -> 396894.05 | L20: =D20/E20 -> 28349.575
D21: =SUM(D15:D20) -> 1500713.5 | G21: =SUM(G15:G20) -> 535176.85 | H21: =SUM(H15:H20) -> 73703.717 | I21: =SUM(I15:I20) -> 608880.57 | J21: =SUM(J15:J20) -> 891832.89
A23: Furniture, Fixtures and Equipment
A24: Furniture and Equipment | C24: Various | D24: 349018 | E24: 7 | F24: S/L | G24: 330026.33 | H24: =3980.07*4 -> 15920.28 | I24: 345946.61 | J24: 3071.39 | L24: =3980.07*4 -> 15920.28
B25: Furniture | C25: 2022 | D25: 3035.85 | E25: 7 | F25: S/L | G25: 867.38571 | H25: =+D25/E25 -> 433.69286 | I25: =+G25+H25 -> 1301.0786 | J25: =+D25-I25 -> 1734.7714 | L25: =D25/E25 -> 433.69286
B26: Furniture | C26: 2023 | D26: 34199.24 | E26: 7 | F26: S/L | G26: 4885.6057 | H26: =+D26/E26 -> 4885.6057 | I26: =+G26+H26 -> 9771.2114 | J26: =+D26-I26 -> 24428.029 | L26: =D26/E26 -> 4885.6057
B27: Furniture | C27: 2024 | D27: 25548.26 | E27: 7 | F27: S/L | G27: 0 | H27: =+D27/E27 -> 3649.7514 | I27: =+G27+H27 -> 3649.7514 | J27: =+D27-I27 -> 21898.509 | L27: =D27/E27 -> 3649.7514
D28: =SUM(D24:D27) -> 411801.35 | G28: =SUM(G24:G27) -> 335779.32 | H28: =SUM(H24:H27) -> 24889.33 | I28: =SUM(I24:I27) -> 360668.65 | J28: =SUM(J24:J27) -> 51132.699
D30: =+D11+D21+D28 -> 1981654 | G30: =+G11+G21+G28 -> 870956.17 | H30: =+H11+H21+H28 -> 98593.047 | I30: =+I11+I21+I28 -> 969549.22 | J30: =+J11+J21+J28 -> 1012104.7 | L30: =SUM(L15:L27) -> 98593.047
F32: 58000 | G32: Depreciation Expense | H32: 98593.05
G33: Variance | H33: =H30-H32 -> -0.0030833333
A35: WPG Notes
A37: Note 1: Building - Keeping with annual depreciation expense of $16K. WPG anticipates building will be fully depreciated in 2032 (i.e. 8 years from now) as a result of accumulated depreciation balance not reflecting the correct estimated annual depreciation recording each year prior to WPG appointment as auditors. WPG noted accumulated depreciation discrepancy in MLC Memorandum. However, we did not propose an AJE to "catch-up" accumulated depreciation because the entry would potentially distort current year expense activity. Reasonable.

Sheet 2023
A1: Turner Theological Seminary
A2: Fixed Asset Additions
A4: FY 2023
A5: Description | C5: Year | D5: Cost | E5: Useful Life | F5: Method | G5: Beg. Accum. Deprec. | H5: Depreciation | I5: End. Accum. Deprec. | J5: Net Book Value
A6: Land
A8: Land-Building | C8: 1986 | D8: 69139.15 | G8: 0 | H8: 0 | I8: =+G8+H8 -> 0 | J8: =+D8-I8 -> 69139.15
A10: Buildings
A12: Buildings and Improvements | C12: 1986 | D12: =701391.48-D8 -> 632252.33 | E12: 40 | F12: S/L | G12: =+'2022'!I12 -> 485159.89 | H12: =+D12/E12 -> 15806.308 | I12: =+G12+H12 -> 500966.2 | J12: =+D12-I12 -> 131286.13
B13: Improvements | C13: 2022 | D13: 33117.29 | E13: 15 | F13: S/L | G13: =+'2022'!I13 -> 2207.8193 | H13: =+D13/E13 -> 2207.8193 | I13: =+G13+H13 -> 4415.6387 | J13: =+D13-I13 -> 28701.651
B14: Improvements | C14: 2022 | D14: 36825 | E14: 15 | F14: S/L | G14: =+'2022'!I14 -> 2455 | H14: =+D14/E14 -> 2455 | I14: =+G14+H14 -> 4910 | J14: =+D14-I14 -> 31915
B15: Improvements | C15: 2023 | D15: =300775.21 -> 300775.21 | E15: 15 | F15: S/L | G15: 0 | H15: =+D15/E15 -> 20051.681 | I15: =+G15+H15 -> 20051.681 | J15: =+D15-I15 -> 280723.53
B16: Improvements | C16: 2023 | D16: 72500 | E16: 15 | F16: S/L | G16: 0 | H16: =+D16/E16 -> 4833.3333 | I16: =+G16+H16 -> 4833.3333 | J16: =+D16-I16 -> 67666.667
D17: =SUM(D12:D16) -> 1075469.8 | G17: =SUM(G12:G16) -> 489822.71 | H17: =SUM(H12:H16) -> 45354.142 | I17: =SUM(I12:I16) -> 535176.85 | J17: =SUM(J12:J16) -> 540292.98
A19: Furniture, Fixtures and Equipment
A21: Furniture and Equipment | C21: Various | D21: 349018 | E21: 7 | F21: S/L | G21: =+'2022'!I19 -> 314106.05 | H21: =3980.07*4 -> 15920.28 | I21: =+G21+H21 -> 330026.33 | J21: =+D21-I21 -> 18991.67
B22: Furniture | C22: 2022 | D22: 3035.85 | E22: 7 | F22: S/L | G22: =+'2022'!I20 -> 433.69286 | H22: =+D22/E22 -> 433.69286 | I22: =+G22+H22 -> 867.38571 | J22: =+D22-I22 -> 2168.4643
B23: Furniture | C23: 2023 | D23: 34199.24 | E23: 7 | F23: S/L | G23: 0 | H23: =+D23/E23 -> 4885.6057 | I23: =+G23+H23 -> 4885.6057 | J23: =+D23-I23 -> 29313.634
D24: =SUM(D21:D23) -> 386253.09 | G24: =SUM(G21:G23) -> 314539.74 | H24: =SUM(H21:H23) -> 21239.579 | I24: =SUM(I21:I23) -> 335779.32 | J24: =SUM(J21:J23) -> 50473.769
D26: =+D8+D17+D24 -> 1530862.1 | G26: =+G8+G17+G24 -> 804362.45 | H26: =+H8+H17+H24 -> 66593.72 | I26: =+I8+I17+I24 -> 870956.17 | J26: =+J8+J17+J24 -> 659905.9
C29: Journal Entries: | G29: DR | H29: CR
D30: 1 | E30: 15010 | G30: 59139.15
D31: 1 | E31: 15020 | H31: =+G30 -> 59139.15
D32: To reclassify land.
D34: 2 | E34: 15021 | G34: =550026.65-I17 -> 14849.801
D35: 2 | E35: 15041 | G35: =336404.65-I24 -> 625.32857
D36: 2 | E36: 50029 | H36: 8235.04
D37: 2 | E37: 58000 | H37: =73833.81-H26 -> 7240.0898
D38: To record additional depreciation expense.

Sheet 2022
A1: Turner Theological Seminary
A2: Fixed Asset Additions
A4: FY 2022
A5: Description | C5: Year | D5: Cost | E5: Useful Life | F5: Method | G5: Beg. Accum. Deprec. | H5: Depreciation | I5: End. Accum. Deprec. | J5: Net Book Value
A6: Land
A8: Land-Building | C8: 1986 | D8: 69139.15 | G8: 0 | H8: 0 | I8: =+G8+H8 -> 0 | J8: =+D8-I8 -> 69139.15
A10: Buildings
A12: Buildings and Improvements | C12: 1986 | D12: =701391.48-D8 -> 632252.33 | E12: 40 | F12: S/L | G12: =+'2021'!I12 -> 469353.58 | H12: =+D12/E12 -> 15806.308 | I12: =+G12+H12 -> 485159.89 | J12: =+D12-I12 -> 147092.44
B13: Improvements | C13: 2022 | D13: 33117.29 | E13: 15 | F13: S/L | G13: 0 | H13: =+D13/E13 -> 2207.8193 | I13: =+G13+H13 -> 2207.8193 | J13: =+D13-I13 -> 30909.471
B14: Improvements | C14: 2022 | D14: 36825 | E14: 15 | F14: S/L | G14: 0 | H14: =+D14/E14 -> 2455 | I14: =+G14+H14 -> 2455 | J14: =+D14-I14 -> 34370
D15: =SUM(D12:D14) -> 702194.62 | G15: =SUM(G12:G14) -> 469353.58 | H15: =SUM(H12:H14) -> 20469.128 | I15: =SUM(I12:I14) -> 489822.71 | J15: =SUM(J12:J14) -> 212371.91
A17: Furniture, Fixtures and Equipment
A19: Furniture and Equipment | C19: Various | D19: 349018 | E19: 7 | F19: S/L | G19: =+'2021'!I16 -> 298185.77 | H19: =3980.07*4 -> 15920.28 | I19: =+G19+H19 -> 314106.05 | J19: =+D19-I19 -> 34911.95
B20: Furniture | C20: 2022 | D20: 3035.85 | E20: 7 | F20: S/L | G20: 0 | H20: =+D20/E20 -> 433.69286 | I20: =+G20+H20 -> 433.69286 | J20: =+D20-I20 -> 2602.1571
D21: =SUM(D19:D20) -> 352053.85 | G21: =SUM(G19:G20) -> 298185.77 | H21: =SUM(H19:H20) -> 16353.973 | I21: =SUM(I19:I20) -> 314539.74 | J21: =SUM(J19:J20) -> 37514.107
D23: =+D8+D15+D21 -> 1123387.6 | G23: =+G8+G15+G21 -> 767539.35 | H23: =+H8+H15+H21 -> 36823.1 | I23: =+I8+I15+I21 -> 804362.45 | J23: =+J8+J15+J21 -> 319025.17
C26: Journal Entries: | G26: DR | H26: CR
D27: 1 | E27: 15010 | G27: 59139.15
D28: 1 | E28: 15020 | H28: =+G27 -> 59139.15
D29: To reclassify land.
D31: 2 | E31: 15021 | G31: 7609.71
D32: 2 | E32: 15041 | G32: 625.33
D33: 2 | E33: 50029 | H33: 994.95
D34: 2 | E34: 58000 | H34: 7240.09
D35: To record additional depreciation expense.

Sheet 2021
A1: Turner Theological Seminary
A2: Fixed Asset Additions
A4: Three months ended June 30, 2021
A5: Description | C5: Year | D5: Cost | E5: Useful Life | F5: Method | G5: Beg. Accum. Deprec. | H5: Depreciation | I5: End. Accum. Deprec. | J5: Net Book Value
A6: Land
A8: Land-Building | C8: 1986 | D8: 69139.15 | G8: 0 | H8: 0 | I8: =+G8+H8 -> 0 | J8: =+D8-I8 -> 69139.15
A10: Buildings
A12: Buildings and Improvements | C12: 1986 | D12: =701391.48-D8 -> 632252.33 | E12: 40 | F12: S/L | G12: =470034.67+5109-9741.67 -> 465402 | H12: 3951.58 | I12: =+G12+H12 -> 469353.58 | J12: =+D12-I12 -> 162898.75
A14: Furniture, Fixtures and Equipment
A16: Furniture and Equipment | C16: Various | D16: 349018 | E16: 7 | F16: S/L | G16: 294831.1 | H16: 3354.67 | I16: =+G16+H16 -> 298185.77 | J16: =+D16-I16 -> 50832.23
D18: =SUM(D8:D17) -> 1050409.5 | G18: =SUM(G8:G17) -> 760233.1 | H18: =SUM(H8:H17) -> 7306.25 | I18: =SUM(I8:I17) -> 767539.35 | J18: =SUM(J8:J17) -> 282870.13
C21: Journal Entries: | G21: DR | H21: CR
D22: 1 | E22: 15010 | G22: 59139.15
D23: 1 | E23: 15020 | H23: =+G22 -> 59139.15
D24: To reclassify land.
D26: 2 | E26: 15021 | G26: 681.09
D27: 2 | E27: 15031 | G27: 5109
D28: 2 | E28: 15041 | H28: 3354.67
D29: 2 | E29: 58000 | H29: 2435.42
D30: To correct accumulated depreciation
