Workbook

Sheet Summary
B1: TURNER THEOLOGICAL SEMINARY
B2: OPERATING BUDGET — FOR THE FISCAL YEARS JULY 1, 2025 THROUGH JUNE 30, 2031
B3: Prepared for: Board of Trustees · TRACS · ATS · SACSCOC · U.S. Department of Education
D5: FY 2025-26 (BUDGET) | E5: FY 2026-27 (BUDGET) | F5: FY 2027-28 (BUDGET) | G5: FY 2028-29 (BUDGET) | H5: FY 2029-30 (BUDGET) | I5: FY 2030-31 (BUDGET)
D6: July 1, 2025 – June 30, 2026 | E6: July 1, 2026 – June 30, 2027 | F6: July 1, 2027 – June 30, 2028 | G6: July 1, 2028 – June 30, 2029 | H6: July 1, 2029 – June 30, 2030 | I6: July 1, 2030 – June 30, 2031
B8: REVENUE AND SUPPORT
B9: Tuition and fees, net | D9: 353800 | E9: 628500 | F9: ='Revenue Detail'!D21 -> 1111470 | G9: ='Revenue Detail'!E21 -> 1468750 | H9: ='Revenue Detail'!F21 -> 1730950 | I9: ='Revenue Detail'!G21 -> 2016550
B10: Private gifts and grants | D10: 911040 | E10: ='Revenue Detail'!C11 -> 911040 | F10: ='Revenue Detail'!D11 -> 1006592 | G10: ='Revenue Detail'!E11 -> 1016552 | H10: ='Revenue Detail'!F11 -> 1016552 | I10: ='Revenue Detail'!G11 -> 1026552
B11: Sales and services of auxiliary enterprises | D11: 1287354 | E11: ='Revenue Detail'!C27 -> 830376 | F11: ='Revenue Detail'!D27 -> 894400 | G11: ='Revenue Detail'!E27 -> 940800 | H11: ='Revenue Detail'!F27 -> 987200 | I11: ='Revenue Detail'!G27 -> 1033600
B12: Endowment Investment Revenue (5% ROI on Endowments) | D12: 47000 | E12: 47000 | F12: =E12*1.03 -> 48410 | G12: =F12*1.03 -> 49862.3 | H12: =G12*1.03 -> 51358.169 | I12: =H12*1.03 -> 52898.914
B13: Scholarship Revenue | D13: 0 | E13: 200000 | F13: =E13*1.03 -> 206000 | G13: =F13*1.03 -> 212180 | H13: =G13*1.03 -> 218545.4 | I13: =H13*1.03 -> 225101.76
B14: Other income | D14: 1000 | E14: 75000 | F14: =E14*1.03 -> 77250 | G14: =F14*1.03 -> 79567.5 | H14: =G14*1.03 -> 81954.525 | I14: =H14*1.03 -> 84413.161
B15: Unrealized gain (loss) on investments | D15: -34597 | E15: 23698 | F15: 23698 | G15: 23698 | H15: 23698 | I15: 23698
B17: TOTAL REVENUES | D17: 2565597 | E17: =SUM(E9:E15) -> 2715614 | F17: 2853590 | G17: 3092898 | H17: 3338798 | I17: 3576698
B19: EXPENSES
B20: Program Services | D20: 1177698 | E20: ='Expense Detail'!C13 -> 1254073 | F20: ='Expense Detail'!D13 -> 1301975.3 | G20: ='Expense Detail'!E13 -> 1340951.8 | H20: ='Expense Detail'!F13 -> 1381290.4 | I20: ='Expense Detail'!G13 -> 1423047.5
B21: Management and General | D21: 824315 | E21: ='Expense Detail'!C28 -> 890844.41 | F21: ='Expense Detail'!D28 -> 1008501.8 | G21: ='Expense Detail'!E28 -> 1343288.4 | H21: ='Expense Detail'!F28 -> 1383784.2 | I21: ='Expense Detail'!G28 -> 1424930.6
B22: Operation of Plant and Maintenance | D22: 334733 | E22: ='Expense Detail'!C39 -> 386739 | F22: ='Expense Detail'!D39 -> 281791.55 | G22: ='Expense Detail'!E39 -> 281785.3 | H22: ='Expense Detail'!F39 -> 294868.86 | I22: ='Expense Detail'!G39 -> 305044.92
B24: TOTAL EXPENSES | D24: 2336746 | E24: =SUM(E20:E22) -> 2531656.4 | F24: 2700000 | G24: 2850000 | H24: 2939700 | I24: 3029650
B26: NET OPERATING SURPLUS (DEFICIT) | D26: 228851 | E26: =E17-E24 -> 183957.59 | F26: 153590 | G26: 242898 | H26: 399098 | I26: 547048
B28: Net Surplus as % of Total Revenue | D28: =D26/D17 -> 0.089199902 | E28: =E26/E17 -> 0.067740698 | F28: =F26/F17 -> 0.053823429 | G28: =G26/G17 -> 0.078534113 | H28: =H26/H17 -> 0.11953344 | I28: =I26/I17 -> 0.15294777
B30: DOE Financial Responsibility Composite Score Trajectory (Target: ≥ 1.5)
B31: Projected Composite Score (Indicative)
B32: * FY2026 = current year estimated; FY2027 = housing transition year; FY2028+ = Title IV approved
B34: KEY ASSUMPTIONS SUMMARY
B35: MDiv Enrollment (Students) | D35: 34 | E35: 67 | F35: 133 | G35: 150 | H35: 165 | I35: 180
B36: Housing Occupancy Rate (Self-Managed) | D36: FY2025-26 Budget | E36: 75% | F36: 80% | G36: 85% | H36: 90% | I36: 95%
B38: Turner Theological Seminary, Inc. · 702 Martin Luther King Jr. Drive SW, Atlanta, GA 30314 · Prepared by: Office of Business & Finance · April 2026
B39: Auxiliary revenue reflects self-managed model (FY2027 forward) at 75% occupancy ramp. FY2026 reflects approved budget under Spelman MOU. Title IV approval assumed FY2027-28.

Sheet Assumptions
A1: BUDGET ASSUMPTIONS — ALL INPUTS ARE ENTERED HERE (BLUE CELLS ONLY)
A2: 🔵 Blue cells = Inputs you can change · All other tabs pull from this sheet · Last Updated: April 2026
A4: ENROLLMENT & TUITION
A5: Assumption | B5: FY 2025-26 | C5: FY 2026-27 | D5: FY 2027-28 | E5: FY 2028-29 | F5: FY 2029-30 | G5: FY 2030-31 | H5: Notes
A6: MDiv Full-Time Enrollment (Students) | B6: 34 | C6: 67 | D6: 133 | E6: 150 | F6: 165 | G6: 180 | H6: FY2028+ assumes Title IV federal aid approved — enrollment accelerates
A7: MDiv Rate (per credit hour) | B7: 650 | C7: 650 | D7: 650 | E7: 650 | F7: 650 | G7: 650 | H7: 72 credit program over 3 years = $15,600/student/yr
A8: Institutional Aid Rate (% of gross tuition) | B8: 0.95 | C8: 0.85 | D8: 0.6 | E8: 0.5 | F8: 0.45 | G8: 0.4 | H8: Declines as Title IV federal aid replaces institutional scholarships
A9: Continuing Ed Enrollment (Students) | B9: 100 | C9: 60 | D9: 65 | E9: 70 | F9: 75 | G9: 80 | H9: Certificate programs
A10: Continuing Ed Revenue (Total) | B10: 225000 | C10: 123750 | D10: 135000 | E10: 146250 | F10: 157500 | G10: 168750 | H10: Rate × enrollment
A11: Jarena Lee Women's Leadership Program | B11: 100000 | C11: 100000 | D11: 100000 | E11: 100000 | F11: 100000 | G11: 100000 | H11: 20 students × $5,000/student
A13: HOUSING REVENUE
A14: Assumption | B14: FY 2025-26 | C14: FY 2026-27 | D14: FY 2027-28 | E14: FY 2028-29 | F14: FY 2029-30 | G14: FY 2030-31 | H14: Notes
A15: Occupancy Rate (Self-Managed Residential) | B15: 0.75 | C15: 0.75 | D15: 0.8 | E15: 0.85 | F15: 0.9 | G15: 0.95 | H15: FY2026 = old Spelman budget rate; FY2027+ = self-managed ramp
A16: Max Annual Residential Revenue (100% Occupancy) | B16: 928000 | C16: 928000 | D16: 928000 | E16: 928000 | F16: 928000 | G16: 928000 | H16: Private Eff $128K + Shd Eff $280K + Pvt Dorm $120K + Shd Dorm $400K
A17: Residential Housing Revenue (at Occupancy Rate) | B17: 1240000 | C17: 696000 | D17: 742400 | E17: 788800 | F17: 835200 | G17: 881600 | H17: Note: FY2026 uses Spelman MOU amount ($1,280,440 contract / ~$1,240K net)
A18: Summer Corporate Housing Revenue | B18: 35354 | C18: 122376 | D18: 140000 | E18: 140000 | F18: 140000 | G18: 140000 | H18: FY2026 misc; FY2027 = A.T.I. confirmed $122,376; FY2028+ = corporate housing program
A19: Facility Rentals, Vending & Other | B19: 12000 | C19: 12000 | D19: 12000 | E19: 12000 | F19: 12000 | G19: 12000 | H19: Misc auxiliary
A21: AME CHURCH & DONOR SUPPORT
A22: Assumption | B22: FY 2025-26 | C22: FY 2026-27 | D22: FY 2027-28 | E22: FY 2028-29 | F22: FY 2029-30 | G22: FY 2030-31 | H22: Notes
A23: Connectional AME Church Support | B23: 180000 | C23: 180000 | D23: 180000 | E23: 180000 | F23: 180000 | G23: 180000 | H23: FY2025 actual $180,102
A24: 6th Episcopal District | B24: 250000 | C24: 250000 | D24: 250000 | E24: 250000 | F24: 250000 | G24: 250000 | H24: Annual appropriation — consistent
A25: Board of Trustees Giving | B25: 100000 | C25: 100000 | D25: 100000 | E25: 100000 | F25: 100000 | G25: 100000 | H25: $100K fiduciary commitment
A26: AME Episcopal Districts (Other) | B26: 70000 | C26: 70000 | D26: 70000 | E26: 70000 | F26: 70000 | G26: 70000 | H26: Scholarship support
A27: Donations & Fundraising | B27: 194040 | C27: 194040 | D27: 194040 | E27: 204000 | F27: 204000 | G27: 214000 | H27: Founders Day + campaigns + alumni
A28: Grants (Lilly Endowment Services Offset) | B28: 117000 | C28: 117000 | D28: 212552 | E28: 212552 | F28: 212552 | G28: 212552 | H28: Collaborative shared services — offsets operating costs
A30: INVESTMENT & OTHER INCOME
A31: Assumption | B31: FY 2025-26 | C31: FY 2026-27 | D31: FY 2027-28 | E31: FY 2028-29 | F31: FY 2029-30 | G31: FY 2030-31 | H31: Notes
A32: Investment / Unrealized Gain (Loss) | B32: -34597 | C32: 23698 | D32: =C32*1.03 -> 24408.94 | E32: =D32*1.03 -> 25141.208 | F32: =E32*1.03 -> 25895.444 | G32: =F32*1.03 -> 26672.308 | H32: From old budget; actual may vary
A33: Endowment Investment Income (5% ROI) | B33: 47000 | C33: 47000 | D33: 47000 | E33: 47000 | F33: 47000 | G33: 47000 | H33: 5% spending policy on endowment funds
A34: Scholarship Revenue | B34: 0 | C34: 200000 | D34: =C34*1.03 -> 206000 | E34: =D34*1.03 -> 212180 | F34: =E34*1.03 -> 218545.4 | G34: =F34*1.03 -> 225101.76
A35: Other Income | B35: 1000 | C35: 75000 | D35: =C35*1.03 -> 77250 | E35: =D35*1.03 -> 79567.5 | F35: =E35*1.03 -> 81954.525 | G35: =F35*1.03 -> 84413.161 | H35: Interest + misc
A37: EXPENSE ASSUMPTIONS
A38: Assumption | B38: FY 2025-26 | C38: FY 2026-27 | D38: FY 2027-28 | E38: FY 2028-29 | F38: FY 2029-30 | G38: FY 2030-31 | H38: Notes
A39: Annual COLA / Expense Escalation Rate | B39: 0.03 | C39: 0.03 | D39: 0.03 | E39: 0.03 | F39: 0.03 | G39: 0.03 | H39: Applied to non-personnel operating expenses
A40: LOC Balance (Pinnacle Financial Partners) | B40: 866645 | C40: =B40/2 -> 433322.5 | D40: 0 | E40: 0 | F40: 0 | G40: 0 | H40: 8.5% interest — paydown modeled FY2028+
A41: LOC Annual Interest Expense | B41: =B40*0.085 -> 73664.825 | C41: =C40*0.085 -> 36832.413 | D41: =C41/2 -> 18416.206 | E41: =E40*0.085 -> 0 | F41: =F40*0.085 -> 0 | G41: =G40*0.085 -> 0 | H41: LOC balance × 8.5% — included in M&G
A42: Building Repairs & Capital (O&P) | B42: 175000 | C42: 100000 | D42: 100000 | E42: 100000 | F42: 100000 | G42: 100000 | H42: FY2026 elevated due to renovations
A44: KEY STRATEGIC MILESTONES
A45: Assumption | B45: FY 2025-26 | C45: FY 2026-27 | D45: FY 2027-28 | E45: FY 2028-29 | F45: FY 2029-30 | G45: FY 2030-31 | H45: Notes
A46: TRACS Candidacy | B46: ✓ | C46: ✓ | D46: ✓ | E46: ✓ | F46: ✓ | G46: ✓ | H46: Confirmed 2025 — 5-year candidacy period
...

Sheet Revenue Detail
A1: REVENUE DETAIL — Turner Theological Seminary | FY2026-FY2031
A2: All values are budgeted figures. Blue = input cells in Assumptions tab. Black = formula-calculated.
A3: Revenue Line | B3: FY 2025-26 | C3: FY 2026-27 | D3: FY 2027-28 | E3: FY 2028-29 | F3: FY 2029-30 | G3: FY 2030-31 | H3: Notes/Driver
A4: AME CHURCH & DENOMINATIONAL SUPPORT
A5: Connectional AME Church | B5: 180000 | C5: 180000 | D5: 180000 | E5: 180000 | F5: 180000 | G5: 180000 | H5: FY2025 actual $180,102
A6: 6th Episcopal District | B6: 250000 | C6: 250000 | D6: 250000 | E6: 250000 | F6: 250000 | G6: 250000 | H6: Annual appropriation
A7: Board of Trustees Giving | B7: 100000 | C7: 100000 | D7: 100000 | E7: 100000 | F7: 100000 | G7: 100000 | H7: $100K fiduciary commitment
A8: AME Episcopal Districts (Other) | B8: 70000 | C8: 70000 | D8: 70000 | E8: 70000 | F8: 70000 | G8: 70000 | H8: Scholarship support
A9: Donations & Fundraising | B9: 194040 | C9: 194040 | D9: 194040 | E9: 204000 | F9: 204000 | G9: 214000 | H9: Founders Day, campaigns, alumni
A10: Grants (Lilly / Other) | B10: 117000 | C10: 117000 | D10: 212552 | E10: 212552 | F10: 212552 | G10: 212552 | H10: Collaborative shared services offset
A11: Subtotal — AME & Donations | B11: 911040 | C11: 911040 | D11: 1006592 | E11: 1016552 | F11: 1016552 | G11: 1026552 | H11: Flows to Summary as 'Private gifts and grants'
A13: TUITION & FEES
A14: MDiv Enrollment (Students) | B14: 34 | C14: 50 | D14: 133 | E14: 150 | F14: 165 | G14: 180 | H14: Annual headcount
A15: MDiv Tuition (Gross) | B15: =B14*15600 -> 530400 | C15: =C14*15600 -> 780000 | D15: =D14*15600 -> 2074800 | E15: =E14*15600 -> 2340000 | F15: =F14*15600 -> 2574000 | G15: =G14*15600 -> 2808000 | H15: Students × $15,600/yr
A16: Institutional Aid (Scholarships) | B16: -503880 | C16: -392750 | D16: =-(D15*Assumptions!D8) -> -1244880 | E16: =-(E15*Assumptions!E8) -> -1170000 | F16: =-(F15*Assumptions!F8) -> -1158300 | G16: =-(G15*Assumptions!G8) -> -1123200 | H16: Declining as Title IV federal aid takes effect
A17: Net MDiv Tuition | B17: =B15+B16 -> 26520 | C17: =C15+C16 -> 387250 | D17: =D15+D16 -> 829920 | E17: =E15+E16 -> 1170000 | F17: =F15+F16 -> 1415700 | G17: =G15+G16 -> 1684800
A18: Continuing Ed Programs | B18: 225000 | C18: 123750 | D18: 135000 | E18: 146250 | F18: 157500 | G18: 168750 | H18: Certificate, LLMV, CWJ programs
A19: Jarena Lee Women's Leadership | B19: 100000 | C19: 100000 | D19: 100000 | E19: 100000 | F19: 100000 | G19: 100000 | H19: 20 students × $5,000
A20: Comprehensive Fees & Other | B20: 50800 | C20: =350*C14 -> 17500 | D20: =350*D14 -> 46550 | E20: =350*E14 -> 52500 | F20: =350*F14 -> 57750 | G20: =350*G14 -> 63000 | H20: App fees, tech fees, admin fees
A21: Net Tuition and Fees (Total) | B21: =SUM(B17:B20) -> 402320 | C21: =SUM(C17:C20) -> 628500 | D21: =SUM(D17:D20) -> 1111470 | E21: =SUM(E17:E20) -> 1468750 | F21: =SUM(F17:F20) -> 1730950 | G21: =SUM(G17:G20) -> 2016550 | H21: Flows to Summary
A23: AUXILIARY ENTERPRISE REVENUE — HOUSING
A24: Residential Housing (Sem. × Rate × Occupancy) | B24: 1240000 | C24: 696000 | D24: 742400 | E24: 788800 | F24: 835200 | G24: 881600 | H24: FY2026 = Spelman MOU rate. FY2027+ = self-managed at 75%→95% ramp
A25: Summer Corporate Housing | B25: 35354 | C25: 122376 | D25: 140000 | E25: 140000 | F25: 140000 | G25: 140000 | H25: FY2027 = A.T.I. $122,376 confirmed; FY2028+ = est.
A26: Facility Rentals, Vending & Misc | B26: 12000 | C26: 12000 | D26: 12000 | E26: 12000 | F26: 12000 | G26: 12000 | H26: Stable minor revenue
A27: Subtotal — Auxiliary Enterprise | B27: 1287354 | C27: 830376 | D27: 894400 | E27: 940800 | F27: 987200 | G27: 1033600 | H27: Flows to Summary
A29: OTHER REVENUE
A30: Philanthropic Revenue/Support (Unrestricted) | C30: 200000 | D30: =C30*1.03 -> 206000 | E30: =D30*1.03 -> 212180 | F30: =E30*1.03 -> 218545.4 | G30: =F30*1.03 -> 225101.76 | H30: Philanthropic Giving
A31: Scholarship Revenue (Restricted Endowment) | B31: 47000 | C31: 47000 | D31: =C31*1.03 -> 48410 | E31: =D31*1.03 -> 49862.3 | F31: =E31*1.03 -> 51358.169 | G31: =F31*1.03 -> 52898.914 | H31: 5% spending policy
A32: Investment Income / Unrealized Gain (Loss) | B32: -34597 | C32: 23698 | D32: =C32*1.03 -> 24408.94 | E32: =D32*1.03 -> 25141.208 | F32: =E32*1.03 -> 25895.444 | G32: =F32*1.03 -> 26672.308 | H32: Portfolio returns
A33: Other Income | B33: 1000 | C33: 75000 | D33: =C33*1.03 -> 77250 | E33: =D33*1.03 -> 79567.5 | F33: =E33*1.03 -> 81954.525 | G33: =F33*1.03 -> 84413.161 | H33: Sponsorships/Sales Activity
A35: TOTAL REVENUES | B35: =B11+B21+B27+B30+B31+B32+B33 -> 2614117 | C35: =C11+C21+C27+C30+C31+C32+C33 -> 2715614 | D35: =D11+D21+D27+D30+D31+D32+D33 -> 3368530.9 | E35: =E11+E21+E27+E30+E31+E32+E33 -> 3792853 | F35: =F11+F21+F27+F30+F31+F32+F33 -> 4112455.5 | G35: =G11+G21+G27+G30+G31+G32+G33 -> 4465788.1

Sheet Housing Scenarios
A1: HOUSING REVENUE SCENARIOS — Self-Managed Talbot Hall | 75% Base Case vs 100% Full Occupancy
A2: FY2026 shows Spelman MOU reference rate. FY2027+ shows self-managed model. Budget uses 75% BASE CASE.
A3: Metric | B3: FY 2025-26 | C3: FY 2026-27 | D3: FY 2027-28 | E3: FY 2028-29 | F3: FY 2029-30 | G3: FY 2030-31 | H3: Notes
A4: BUILDING CAPACITY — TALBOT HALL (Self-Managed Model)
A5: Private Efficiency Rooms (8 rooms) | B5: 8 | C5: 8 | D5: 8 | E5: 8 | F5: 8 | G5: 8 | H5: $8,000/resident/semester (rate+amenity)
A6: Shared Efficiency Rooms (10 rooms) | B6: 10 | C6: 10 | D6: 10 | E6: 10 | F6: 10 | G6: 10 | H6: $7,000/resident/semester, max 2 residents
A7: Private Dorm Rooms (10 rooms) | B7: 10 | C7: 10 | D7: 10 | E7: 10 | F7: 10 | G7: 10 | H7: $6,000/resident/semester
A8: Shared Dorm Rooms (20 rooms) | B8: 20 | C8: 20 | D8: 20 | E8: 20 | F8: 20 | G8: 20 | H8: $5,000/resident/semester, max 2 residents
A9: Total Leasable Rooms | B9: 48 | C9: 48 | D9: 48 | E9: 48 | F9: 48 | G9: 48
A10: Max Annual Residential Revenue (100% Occupancy) | B10: 928000 | C10: 928000 | D10: 928000 | E10: 928000 | F10: 928000 | G10: 928000 | H10: Both semesters
A12: SCENARIO A — 75% BASE CASE (BUDGET MODEL)
A13: Occupancy Rate (Residential — 2 semesters) | B13: 0.75 | C13: 0.75 | D13: 0.8 | E13: 0.85 | F13: 0.9 | G13: 0.95 | H13: FY2026 = Spelman MOU; FY2027 starts at 75%, +5%/yr
A14: Residential Revenue | B14: 1240000 | C14: 696000 | D14: 742400 | E14: 788800 | F14: 835200 | G14: 881600 | H14: FY2026 = Spelman contract ($1.28M / 2 sems in FY year)
A15: Summer Corporate Housing Revenue | B15: 35354 | C15: 122376 | D15: 140000 | E15: 140000 | F15: 140000 | G15: 140000 | H15: A.T.I. $122,376 confirmed FY2027; est. $140K FY2028+
A16: Facility Rentals & Vending | B16: 12000 | C16: 12000 | D16: 12000 | E16: 12000 | F16: 12000 | G16: 12000 | H16: Stable
A17: TOTAL AUXILIARY — 75% Scenario | B17: 1287354 | C17: 830376 | D17: 894400 | E17: 940800 | F17: 987200 | G17: 1033600 | H17: Used in Budget Summary & Revenue Detail
A19: SCENARIO B — 100% FULL OCCUPANCY (UPSIDE CASE)
A20: Occupancy Rate (Residential) | B20: 1 | C20: 1 | D20: 1 | E20: 1 | F20: 1 | G20: 1 | H20: 100% in all rooms
A21: Residential Revenue | B21: 1280440 | C21: 928000 | D21: 928000 | E21: 928000 | F21: 928000 | G21: 928000 | H21: FY2026 = actual Spelman contract value
A22: Summer Corporate Housing Revenue | B22: 35354 | C22: 122376 | D22: 140000 | E22: 140000 | F22: 140000 | G22: 140000 | H22: Same as base case
A23: Facility Rentals & Vending | B23: 12000 | C23: 12000 | D23: 12000 | E23: 12000 | F23: 12000 | G23: 12000 | H23: Same as base case
A24: TOTAL AUXILIARY — 100% Scenario | B24: 1327794 | C24: 1062376 | D24: 1080000 | E24: 1080000 | F24: 1080000 | G24: 1080000 | H24: Revenue upside vs base case
A26: VARIANCE — 100% vs 75% (REVENUE UPSIDE)
A27: Additional Revenue at 100% Occupancy | B27: 40440 | C27: 232000 | D27: 185600 | E27: 139200 | F27: 92800 | G27: 46400 | H27: Represents unfilled room potential
A29: RATE REFERENCE TABLE — Talbot Hall (Effective FY2027 Self-Managed Rates)
A30: Private Efficiency (8 rooms, 1 resident) | B30: 7500 | C30: 500 | D30: 8000 | E30: 8000 | F30: 16000 | G30: 256000 | H30: Single occupant
A31: Shared Efficiency (10 rooms, 2 residents) | B31: 6500 | C31: 500 | D31: 7000 | E31: 14000 | F31: 28000 | G31: 560000 | H31: Max 2 residents
A32: Private Dorm (10 rooms, 1 resident) | B32: 5500 | C32: 500 | D32: 6000 | E32: 6000 | F32: 12000 | G32: 240000 | H32: Single occupant
A33: Shared Dorm (20 rooms, 2 residents) | B33: 4500 | C33: 500 | D33: 5000 | E33: 10000 | F33: 20000 | G33: 800000 | H33: Max 2 residents

Sheet Annual Report
A1: ANNUAL BUDGET REPORT — Select Fiscal Year:
B2: Selected Fiscal Year: | C2: FY 2026-27 (July 1, 2026 – June 30, 2027)
B3: ↑ Update this cell to change the year displayed below
A5: TURNER THEOLOGICAL SEMINARY OPERATING BUDGET — FY 2026-27 July 1, 2026 – June 30, 2027
B6: BUDGET CATEGORY | C6: FY 2026-27 | D6: % OF REVENUE
A7: REVENUE AND SUPPORT
B8: Tuition and fees, net | C8: 628500 | D8: =C8/$C$15 -> 0.23143937
B9: Private gifts and grants | C9: ='Revenue Detail'!C11 -> 911040 | D9: =C9/$C$15 -> 0.33548214
B10: Sales and services of auxiliary enterprises | C10: ='Revenue Detail'!C27 -> 830376 | D10: =C10/$C$15 -> 0.30577836
B11: Scholarship revenue | C11: ='Revenue Detail'!C30 -> 200000 | D11: =C11/$C$15 -> 0.073648169
B12: Endowment Investment Income | C12: ='Revenue Detail'!C31 -> 47000 | D12: =C12/$C$15 -> 0.01730732
B13: Other income | C13: ='Revenue Detail'!C33 -> 75000 | D13: =C13/$C$15 -> 0.027618064
B14: Unrealized gain (loss) on investments | C14: ='Revenue Detail'!C32 -> 23698 | D14: =C14/$C$15 -> 0.0087265716
B15: TOTAL REVENUES | C15: =SUM(C8:C14) -> 2715614 | D15: 1
A17: EXPENSES
B18: Program Services | C18: ='Expense Detail'!C13 -> 1254073 | D18: =C18/$C$15 -> 0.4618009
B19: Management and General | C19: ='Expense Detail'!C28 -> 890844.41 | D19: =C19/$C$15 -> 0.3280453
B20: Operation of Plant and Maintenance | C20: ='Expense Detail'!C39 -> 386739 | D20: =C20/$C$15 -> 0.1424131
B21: TOTAL EXPENSES | C21: =SUM(C18:C20) -> 2531656.4 | D21: =SUM(D18:D20) -> 0.9322593
B23: NET OPERATING SURPLUS (DEFICIT) | C23: =C15-C21 -> 183957.59 | D23: =C23/$C$15 -> 0.067740698 | F23: =C23-'Expense Detail'!C43 -> 0
A25: KEY ASSUMPTIONS
B26: MDiv Enrollment | C26: 67
B27: Housing Occupancy Rate (Self-Managed) | C27: 75%
B28: Title IV / PPA Status | C28: Pending USDE Approval
B29: LOC Balance (Pinnacle Financial Partners) | C29: 866645
B30: Annual LOC Interest Expense (8.5%) | C30: =C29*0.085 -> 73664.825
A32: Turner Theological Seminary, Inc. · 702 Martin Luther King Jr. Drive SW, Atlanta, GA 30314 · Office of Business & Finance

Sheet Expense Detail
A1: EXPENSE DETAIL — Turner Theological Seminary | FY2026-FY2031
A2: COLA: 3% applied annually to non-personnel operating expenses. Personnel additions in year shown as 'new hire'.
A3: Functional Expense | B3: FY 2025-26 | C3: FY 2026-27 | D3: FY 2027-28 | E3: FY 2028-29 | F3: FY 2029-30 | G3: FY 2030-31 | H3: Notes/Driver
A4: PROGRAM SERVICES
A5: Personnel — Program Staff | B5: 392000 | C5: =237007+254877 -> 491884 | D5: 628000 | E5: 683000 | F5: 703000 | G5: 724000 | H5: Includes academic, enrollment, IE, fin aid staff (Title IV FY2028)
A6: Faculty Compensation (Current) | B6: 217000 | C6: =B6*1.03 -> 223510 | D6: =C6*1.03 -> 230215.3 | E6: =D6*1.03 -> 237121.76 | F6: =E6*1.03 -> 244235.41 | G6: =F6*1.03 -> 251562.47 | H6: 5 PT + curriculum
A7: Additional Faculty (New) | B7: 0 | C7: 0 | D7: 120000 | E7: 124000 | F7: 128000 | G7: 132000 | H7: Hired FY2028 with enrollment growth
A8: Accreditation Fees (TRACS, SACS, ATS, GNPEC) | B8: 112143 | C8: 35000 | D8: 35000 | E8: 35000 | F8: 35000 | G8: 35000 | H8: FY2026 elevated (candidacy fees). Normalizes FY2027+
A9: Scholarships (Institutional Aid — Non-MDiv) | B9: 101000 | C9: 80000 | D9: 60000 | E9: 50000 | F9: 45000 | G9: 40000 | H9: Declining as Title IV federal aid takes over
A10: Academic Technology & Library | B10: 55000 | C10: 56650 | D10: 58350 | E10: 60100 | F10: 61900 | G10: 63760 | H10: 3% COLA
A11: Student Services & Enrollment | B11: 45000 | C11: 0 | D11: 0 | E11: 0 | F11: 0 | G11: 0 | H11: 3% COLA (Vacant)
A12: Other Program Expenses | B12: 255555 | C12: 367029 | D12: 170410 | E12: 151730 | F12: 164155 | G12: 176725 | H12: Travel, events, communications, materials
A13: SUBTOTAL — Program Services | B13: =SUM(B5:B12) -> 1177698 | C13: =SUM(C5:C12) -> 1254073 | D13: =SUM(D5:D12) -> 1301975.3 | E13: =SUM(E5:E12) -> 1340951.8 | F13: =SUM(F5:F12) -> 1381290.4 | G13: =SUM(G5:G12) -> 1423047.5
A15: MANAGEMENT & GENERAL
A16: Personnel — Executive & Administrative | B16: 444224 | C16: 538393 | D16: 550000 | E16: 660000 | F16: 680000 | G16: 700000 | H16: Includes President, CAO, Admin teams
A17: AVP of Advancement (New Hire) | B17: 0 | C17: 0 | D17: 115000 | E17: 118450 | F17: 122000 | G17: 125700 | H17: Hired FY2028 post-accreditation
A18: AVP Business & Finance (New Hire) | B18: 0 | C18: 0 | D18: 0 | E18: 115000 | F18: 118450 | G18: 122000 | H18: Hired FY2029
A19: AVP Administration (New Hire) | B19: 0 | C19: 0 | D19: 0 | E19: 115000 | F19: 118450 | G19: 122000 | H19: Hired FY2029
A20: LOC Interest Expense (Pinnacle LOC) | B20: 73665 | C20: =Assumptions!C41 -> 36832.413 | D20: =Assumptions!D41 -> 18416.206 | E20: =Assumptions!E41 -> 0 | F20: =Assumptions!F41 -> 0 | G20: =Assumptions!G41 -> 0 | H20: 8.5% on declining balance — paydown FY2027
A21: Accounting & Audit | B21: 24000 | C21: =B21*1.03 -> 24720 | D21: =C21*1.03 -> 25461.6 | E21: =D21*1.03 -> 26225.448 | F21: =E21*1.03 -> 27012.211 | G21: =F21*1.03 -> 27822.578 | H21: 3% COLA
A22: Insurance (Officers, Property & Casualty) | B22: 44308 | C22: 45637 | D22: 47006 | E22: 48416 | F22: 49869 | G22: 51365 | H22: 3% COLA
A23: Advertising, Marketing & Promotions | B23: 95897 | C23: 98774 | D23: 101737 | E23: 104789 | F23: 107933 | G23: 111171 | H23: 3% COLA
A24: Payroll Processing & Bank Fees | B24: 13000 | C24: 13390 | D24: 13791 | E24: 14205 | F24: 14631 | G24: 15070 | H24: 3% COLA
A25: Travel & Meetings | B25: 35000 | C25: 36050 | D25: 37131 | E25: 38245 | F25: 39392 | G25: 40574 | H25: 3% COLA
A26: Founders Day & Special Events | B26: 63894 | C26: 65811 | D26: 67785 | E26: 69819 | F26: 71914 | G26: 74071 | H26: 3% COLA
A27: Supplies, Software, Office & Other | B27: 30327 | C27: 31237 | D27: 32174 | E27: 33139 | F27: 34133 | G27: 35157 | H27: 3% COLA
A28: SUBTOTAL — Management & General | B28: =SUM(B16:B27) -> 824315 | C28: =SUM(C16:C27) -> 890844.41 | D28: =SUM(D16:D27) -> 1008501.8 | E28: =SUM(E16:E27) -> 1343288.4 | F28: =SUM(F16:F27) -> 1383784.2 | G28: =SUM(G16:G27) -> 1424930.6
A30: OPERATION OF PLANT & MAINTENANCE
A31: Personnel — Facilities & Security | B31: 166000 | C31: 96885 | D31: =C31*1.03 -> 99791.55 | E31: =D31*1.03 -> 102785.3 | F31: =E31*1.03 -> 105868.86 | G31: =F31*1.03 -> 109044.92 | H31: Security team + coordinator + facility mgr
A32: Building Repairs & Maintenance | B32: 175000 | C32: 100000 | D32: 100000 | E32: 100000 | F32: 100000 | G32: 100000 | H32: FY2026 elevated for renovations; $100K/yr maintenance reserve
A33: Utilities | B33: 36954 | C33: 38063 | D33: 39205 | E33: 40381 | F33: 41593 | G33: 42841 | H33: 3% COLA from FY2026 actual
A34: Property & Casualty Insurance | B34: 0 | C34: 0 | D34: 0 | E34: 0 | F34: 0 | G34: 0 | H34: Included in M&G above
A35: Contracted Services (Grounds, Elevator, Pest) | B35: 20000 | C35: 20600 | D35: 21218 | E35: 21855 | F35: 22510 | G35: 23185 | H35: 3% COLA
A36: Garbage Removal & Janitorial | B36: 18000 | C36: 18540 | D36: 19096 | E36: 19669 | F36: 20259 | G36: 20867 | H36: 3% COLA
A37: CORT Furniture Lease | B37: 62928 | C37: 62928 | D37: 0 | E37: 0 | F37: 0 | G37: 0 | H37: FY2026 final year — Spelman agreement. Self-managed rooms not needing CORT.
A38: Capital & Other Plant Expenses | B38: -143149 | C38: 49723 | D38: 2481 | E38: -2905 | F38: 4638 | G38: 9107 | H38: Residual — balances to subtotal
A39: SUBTOTAL — Operations & Plant | B39: =SUM(B31:B38) -> 335733 | C39: =SUM(C31:C38) -> 386739 | D39: =SUM(D31:D38) -> 281791.55 | E39: =SUM(E31:E38) -> 281785.3 | F39: =SUM(F31:F38) -> 294868.86 | G39: =SUM(G31:G38) -> 305044.92
A41: TOTAL EXPENSES | B41: =B13+B28+B39 -> 2337746 | C41: =C13+C28+C39 -> 2531656.4 | D41: =D13+D28+D39 -> 2592268.7 | E41: =E13+E28+E39 -> 2966025.5 | F41: =F13+F28+F39 -> 3059943.5 | G41: =G13+G28+G39 -> 3153023
A43: Net Operating Surplus (Deficit) | B43: ='Revenue Detail'!B35-'Expense Detail'!B41 -> 276371 | C43: ='Revenue Detail'!C35-'Expense Detail'!C41 -> 183957.59 | D43: ='Revenue Detail'!D35-'Expense Detail'!D41 -> 776262.28 | E43: ='Revenue Detail'!E35-'Expense Detail'!E41 -> 826827.5 | F43: ='Revenue Detail'!F35-'Expense Detail'!F41 -> 1052512.1 | G43: ='Revenue Detail'!G35-'Expense Detail'!G41 -> 1312765.2 | H43: Positive = surplus; negative = deficit

Sheet Personnel Model
A1: PERSONNEL MODEL — Turner Theological Seminary | FY2026-FY2031
A2: Teal = new hire position | 3% annual COLA applied to current positions | All salaries are budgeted amounts
A3: Position | B3: Dept | C3: Salary | D3: Benefits | E3: Payroll Tax | F3: Total Cost | G3: Status | H3: Notes
A4: OFFICE OF THE PRESIDENT
A5: President | B5: M | C5: 150000 | D5: 82790 | E5: 11475 | F5: 244265 | G5: Filled | H5: M — Mgmt & General
A6: Administrative Assistant | B6: M | C6: 30000 | D6: 0 | E6: 0 | F6: 30000 | G6: Filled | H6: M — Mgmt & General
A7: Special Assistant to President | B7: M | C7: 12000 | D7: 0 | E7: 918 | F7: 12918 | G7: Filled | H7: M — Mgmt & General
A8: Administrative Support | B8: M | C8: 35360 | D8: 0 | E8: 2705 | F8: 38065 | G8: Filled | H8: M — Mgmt & General
A9: Office of the President Total (Filled Positions) | F9: 325248
A10: ACADEMIC AFFAIRS
A11: Chief Academic Officer | B11: P | C11: 115000 | D11: 23000 | E11: 8797 | F11: 146797 | G11: Filled | H11: P — Program
A12: Enrollment Management Director | B12: P | C12: 25000 | D12: 0 | E12: 0 | F12: 25000 | G12: Filled | H12: P — Program
A13: Faculty (5 Part-Time) | B13: P | C13: 90000 | D13: 0 | E13: 6885 | F13: 96885 | G13: Filled | H13: P — Program
A14: Student Services Director | B14: P | C14: 35000 | D14: 0 | E14: 2677 | F14: 37677 | G14: FY2028 — Title IV | H14: P — Program
A15: Additional Faculty (FT) | B15: P | C15: 120000 | D15: 0 | E15: 9180 | F15: 129180 | G15: FY2028 — Title IV | H15: P — Program
A16: Admissions & Retention | B16: P | C16: 30000 | D16: 0 | E16: 3825 | F16: 53825 | G16: Eliminated | H16: P — Program
A17: Academic Affairs Total (Filled Positions) | F17: 268682
A18: ADVANCEMENT
A19: AVP of Advancement | B19: M | C19: 90000 | D19: 18000 | E19: 6885 | F19: 114885 | G19: FY2028 | H19: M — Mgmt & General
A20: Exec. Director of Institutional Advancement, Enrollment Strategy, and Housing Operations | B20: M | C20: 55000 | D20: 0 | E20: 4207 | F20: 59207 | G20: Filled | H20: M — Mgmt & General
A21: Advancement Total (Filled Positions) | F21: 59207
A22: BUSINESS & FINANCE
A23: Controller | B23: M | C23: 55000 | D23: 0 | E23: 4207 | F23: 59207 | G23: Filled | H23: M — Mgmt & General
A24: Facilities, Operations Manager & Accounting Support | B24: M | C24: 55000 | D24: 0 | E24: 4207 | F24: 59207 | G24: Filled | H24: M — Mgmt & General
A25: AVP of Business & Finance | B25: M | C25: 115000 | D25: 0 | E25: 8797 | F25: 123797 | G25: FY2029 | H25: M — Mgmt & General
A26: Accounting & Operations | B26: M | C26: 24000 | D26: 0 | E26: 1836 | F26: 25836 | G26: Eliminated | H26: M — Mgmt & General
A27: Finance & Compliance | B27: M | C27: 24000 | D27: 0 | E27: 1836 | F27: 25836 | G27: Eliminated | H27: M — Mgmt & General
A28: Director of Business & Finance | B28: M | C28: 75000 | D28: 0 | E28: 1836 | F28: 25836 | G28: Eliminated | H28: M — Mgmt & General
A29: Business & Finance Total (Filled Positions) | F29: 118414
A30: ADMINISTRATION & OPERATIONS
A31: Human Resources Manager | B31: M | C31: 18000 | D31: 0 | E31: 1377 | F31: 19377 | G31: Filled | H31: M — Mgmt & General
A32: HR & Finance Support | B32: M | C32: 14400 | D32: 0 | E32: 1147 | F32: 16147 | G32: Filled | H32: M — Mgmt & General
A33: Security Team | B33: O | C33: 90000 | D33: 0 | E33: 6885 | F33: 96885 | G33: Filled | H33: O — Operations
A34: Director of Spiritual Life | B34: P | C34: 28800 | D34: 0 | E34: 2203 | F34: 31003 | G34: Filled | H34: P — Program
A35: IT Department | B35: P | C35: 14400 | D35: 0 | E35: 0 | F35: 14400 | G35: Filled | H35: P — Program
A36: AVP of Administration | B36: M | C36: 115000 | D36: 0 | E36: 8797 | F36: 123797 | G36: FY2029 | H36: M — Mgmt & General
A37: Facility & Security Mgr | B37: O | C37: 36000 | D37: 0 | E37: 2754 | F37: 38754 | G37: Eliminated | H37: O — Operations
A38: Security Coordinator | B38: O | C38: 28288 | D38: 0 | E38: 2164 | F38: 30452 | G38: Eliminated | H38: O — Operations
A39: Administration & Operations Total (Filled Positions) | F39: 177812
A40: INSTITUTIONAL EFFECTIVENESS
...
